Traceback (most recent call last):
  File "/home/dkeathley/anaconda3/lib/python3.8/site-packages/jupyter_cache/executors/utils.py", line 51, in single_nb_execution
    executenb(
  File "/home/dkeathley/anaconda3/lib/python3.8/site-packages/nbclient/client.py", line 1204, in execute
    return NotebookClient(nb=nb, resources=resources, km=km, **kwargs).execute()
  File "/home/dkeathley/anaconda3/lib/python3.8/site-packages/nbclient/util.py", line 84, in wrapped
    return just_run(coro(*args, **kwargs))
  File "/home/dkeathley/anaconda3/lib/python3.8/site-packages/nbclient/util.py", line 62, in just_run
    return loop.run_until_complete(coro)
  File "/home/dkeathley/anaconda3/lib/python3.8/asyncio/base_events.py", line 616, in run_until_complete
    return future.result()
  File "/home/dkeathley/anaconda3/lib/python3.8/site-packages/nbclient/client.py", line 663, in async_execute
    await self.async_execute_cell(
  File "/home/dkeathley/anaconda3/lib/python3.8/site-packages/nbclient/client.py", line 965, in async_execute_cell
    await self._check_raise_for_error(cell, cell_index, exec_reply)
  File "/home/dkeathley/anaconda3/lib/python3.8/site-packages/nbclient/client.py", line 862, in _check_raise_for_error
    raise CellExecutionError.from_cell_and_msg(cell, exec_reply_content)
nbclient.exceptions.CellExecutionError: An error occurred while executing the following cell:
------------------
def correlation_ss_gtt(H, tlist, c_ops, a_op, b_op, c_op, d_op, rho0=None):
    return mesolve(H, d_op * rho0 * a_op, tlist, c_ops, [b_op * c_op]).expect[0]

# calculate the two-time correlation functions
taulist = np.linspace(0, 40, 40)
t=5
rho0 = ket2dm(psi_out.states[t])

n_th = background_photons  # bath temperature in terms of excitation number
c_ops = [sqrt(G1*(1+n_th)) * a, sqrt(G1*n_th) * a.dag()]


G2_aa = correlation_ss_gtt(Hab, taulist, c_ops, a.dag(), a, a.dag(), a, rho0=rho0)
G2_bb = correlation_ss_gtt(Hab, taulist, c_ops, b.dag(), b, b.dag(), b, rho0=rho0)
G2_ab = correlation_ss_gtt(Hab, taulist, c_ops, a.dag(), b, a, b.dag(), rho0=rho0)

------------------

[0;31m---------------------------------------------------------------------------[0m
[0;31mNameError[0m                                 Traceback (most recent call last)
[0;32m/tmp/ipykernel_967601/2021380601.py[0m in [0;36m<cell line: 10>[0;34m()[0m
[1;32m      8[0m [0;34m[0m[0m
[1;32m      9[0m [0mn_th[0m [0;34m=[0m [0mbackground_photons[0m  [0;31m# bath temperature in terms of excitation number[0m[0;34m[0m[0;34m[0m[0m
[0;32m---> 10[0;31m [0mc_ops[0m [0;34m=[0m [0;34m[[0m[0msqrt[0m[0;34m([0m[0mG1[0m[0;34m*[0m[0;34m([0m[0;36m1[0m[0;34m+[0m[0mn_th[0m[0;34m)[0m[0;34m)[0m [0;34m*[0m [0ma[0m[0;34m,[0m [0msqrt[0m[0;34m([0m[0mG1[0m[0;34m*[0m[0mn_th[0m[0;34m)[0m [0;34m*[0m [0ma[0m[0;34m.[0m[0mdag[0m[0;34m([0m[0;34m)[0m[0;34m][0m[0;34m[0m[0;34m[0m[0m
[0m[1;32m     11[0m [0;34m[0m[0m
[1;32m     12[0m [0;34m[0m[0m

[0;31mNameError[0m: name 'G1' is not defined
NameError: name 'G1' is not defined

